Workbook

Sheet Lisez-moi
A1: Paname-Panade — référentiel des lieux
A3: Principe : tu ne remplis QUE ce qu'une machine ne peut pas deviner.
A4: Tout le reste (horaires, accessibilité, tarifs détaillés, descriptions) sera récupéré automatiquement
A5: à partir des URL. Ne recopie JAMAIS le texte d'une page dans ce fichier.
A7: Code couleur
A8: Jaune → à remplir à la main (c'est ton seul travail)
A9: Gris → calculé automatiquement depuis l'onglet Familles, ne pas toucher
A10: Vert → sera rempli par le script, laisse vide
A12: Ta boucle de travail, environ 2 minutes par lieu
A13: 1. Ouvre le site du lieu
A14: 2. Colle l'URL de la page qui LISTE les expos (pas une expo précise) dans expos_url
A15: 3. Colle l'URL de la page tarifs/infos pratiques dans tarifs_url
... A32: billetterie → identique pour tout un réseau, vit dans l'onglet Familles

Sheet Familles
A1: famille_id | B1: libellé | C1: gratuite_permanent | D1: gratuite_temporaire | E1: age_max | F1: conditions | G1: source / à vérifier
A2: paris_musees | B2: Paris Musées (Ville de Paris) | C2: Gratuit pour tous | D2: Payant pour tous (gratuit -18 ans) | F2: Collections permanentes en accès libre, sans réservation | G2: Confirmé par tes 3 lignes déjà saisies (Balzac, Bourdelle, Carnavalet)
A3: musee_national | B3: Musée national (Ministère de la Culture) | C3: Gratuit | D3: Variable selon l'établissement | E3: 26 | F3: Résident de longue durée UE/EEE, pièce d'identité exigée | G3: culture.gouv.fr — mesure du 4 avril 2009
A4: cmn | B4: Monument national (CMN) | C4: Gratuit | D4: Généralement inclus dans le billet | E4: 26 | F4: Résident de longue durée UE/EEE (>3 mois), pièce d'identité | G4: Même dispositif national que les musées nationaux
A5: militaire | B5: Musée militaire / de service | C5: À VÉRIFIER | D5: À VÉRIFIER | F5: Règles propres, souvent gratuit -18 ans ou gratuit pour tous | G5: À vérifier lieu par lieu
A6: prive_assoc | B6: Privé / associatif / fondation | C6: À VÉRIFIER | D6: À VÉRIFIER | F6: Règle propre à chaque lieu, aucune généralisation possible | G6: À vérifier lieu par lieu
A7: autre_public | B7: Autre établissement public | C7: À VÉRIFIER | D7: À VÉRIFIER | F7: EPIC, université, collectivité — règle propre | G7: À vérifier lieu par lieu
A9: Vérifie ces 6 lignes une seule fois. Corriger une ligne ici corrige tous les lieux de la famille.
A10: C'est le cœur du système : 6 vérifications au lieu de 56.

Sheet Lieux
A1: id | B1: nom | C1: famille | D1: confiance_famille | E1: règle permanent (héritée) | F1: règle temporaire (héritée) | G1: âge max (hérité) | H1: expos_url | I1: tarifs_url | J1: gratuite_override | K1: statut | L1: date_verif | M1: notes | N1: tier | O1: plateforme_billetterie | P1: notes_crawler | Q1: logo_url | R1: horaires_url
A2: maison-de-balzac | B2: Maison de Balzac | C2: paris_musees | D2: sûr | E2: =IFERROR(IF(INDEX(Familles!$C$2:$C$7,MATCH($C2,Familles!$A$2:$A$7,0))="","",INDEX(Familles!$C$2:$C$7,MATCH($C2,Familles!$A$2:$A$7,0))),"") -> Gratuit pour tous | F2: =IFERROR(IF(INDEX(Familles!$D$2:$D$7,MATCH($C2,Familles!$A$2:$A$7,0))="","",INDEX(Familles!$D$2:$D$7,MATCH($C2,Familles!$A$2:$A$7,0))),"") -> Payant pour tous (gratuit -18 ans) | G2: =IFERROR(IF(INDEX(Familles!$E$2:$E$7,MATCH($C2,Familles!$A$2:$A$7,0))="","",INDEX(Familles!$E$2:$E$7,MATCH($C2,Familles!$A$2:$A$7,0))),"") | H2: https://www.maisondebalzac.paris.fr/ | K2: à vérifier | M2: Déjà saisi | N2: T1 | O2: billetterie-parismusees.paris.fr | P2: Reseau Paris Musees : les 14 sites partagent le MEME gabarit Drupal. Meme structure de menu (Votre visite / Expositions / Agenda), memes images sous /sites/default/files/styles/, meme balise og:image exploitable, et un /sitemap sur chaque site. UN SEUL crawler couvre les 14. Attention : le chemin exact de la page expos varie legerement d'un site a l'autre (/expositions/exposition-en-cours, /expositions/expositions-en-cours, /visiter/expositions/expositions-en-cours) : a confirmer site par site.
A3: musee-bourdelle | B3: Musée Bourdelle | C3: paris_musees | D3: sûr | E3: =IFERROR(IF(INDEX(Familles!$C$2:$C$7,MATCH($C3,Familles!$A$2:$A$7,0))="","",INDEX(Familles!$C$2:$C$7,MATCH($C3,Familles!$A$2:$A$7,0))),"") -> Gratuit pour tous | F3: =IFERROR(IF(INDEX(Familles!$D$2:$D$7,MATCH($C3,Familles!$A$2:$A$7,0))="","",INDEX(Familles!$D$2:$D$7,MATCH($C3,Familles!$A$2:$A$7,0))),"") -> Payant pour tous (gratuit -18 ans) | G3: =IFERROR(IF(INDEX(Familles!$E$2:$E$7,MATCH($C3,Familles!$A$2:$A$7,0))="","",INDEX(Familles!$E$2:$E$7,MATCH($C3,Familles!$A$2:$A$7,0))),"") | H3: https://www.bourdelle.paris.fr/ | K3: à vérifier | M3: Déjà saisi | N3: T1 | O3: billetterie-parismusees.paris.fr | P3: Reseau Paris Musees : les 14 sites partagent le MEME gabarit Drupal. Meme structure de menu (Votre visite / Expositions / Agenda), memes images sous /sites/default/files/styles/, meme balise og:image exploitable, et un /sitemap sur chaque site. UN SEUL crawler couvre les 14. Attention : le chemin exact de la page expos varie legerement d'un site a l'autre (/expositions/exposition-en-cours, /expositions/expositions-en-cours, /visiter/expositions/expositions-en-cours) : a confirmer site par site.
A4: musee-carnavalet-histoire-de-paris | B4: Musée Carnavalet - histoire de Paris | C4: paris_musees | D4: sûr | E4: =IFERROR(IF(INDEX(Familles!$C$2:$C$7,MATCH($C4,Familles!$A$2:$A$7,0))="","",INDEX(Familles!$C$2:$C$7,MATCH($C4,Familles!$A$2:$A$7,0))),"") -> Gratuit pour tous | F4: =IFERROR(IF(INDEX(Familles!$D$2:$D$7,MATCH($C4,Familles!$A$2:$A$7,0))="","",INDEX(Familles!$D$2:$D$7,MATCH($C4,Familles!$A$2:$A$7,0))),"") -> Payant pour tous (gratuit -18 ans) | G4: =IFERROR(IF(INDEX(Familles!$E$2:$E$7,MATCH($C4,Familles!$A$2:$A$7,0))="","",INDEX(Familles!$E$2:$E$7,MATCH($C4,Familles!$A$2:$A$7,0))),"") | H4: https://www.carnavalet.paris.fr/ | K4: à vérifier | M4: Déjà saisi | N4: T1 | O4: billetterie-parismusees.paris.fr | P4: Reseau Paris Musees : les 14 sites partagent le MEME gabarit Drupal. Meme structure de menu (Votre visite / Expositions / Agenda), memes images sous /sites/default/files/styles/, meme balise og:image exploitable, et un /sitemap sur chaque site. UN SEUL crawler couvre les 14. Attention : le chemin exact de la page expos varie legerement d'un site a l'autre (/expositions/exposition-en-cours, /expositions/expositions-en-cours, /visiter/expositions/expositions-en-cours) : a confirmer site par site.
A5: musee-cernuschi-musee-des-arts-de-l-asie-de-la-ville-de-pari | B5: Musée Cernuschi, musée des arts de l'Asie de la ville de Paris | C5: paris_musees | D5: sûr | E5: =IFERROR(IF(INDEX(Familles!$C$2:$C$7,MATCH($C5,Familles!$A$2:$A$7,0))="","",INDEX(Familles!$C$2:$C$7,MATCH($C5,Familles!$A$2:$A$7,0))),"") -> Gratuit pour tous | F5: =IFERROR(IF(INDEX(Familles!$D$2:$D$7,MATCH($C5,Familles!$A$2:$A$7,0))="","",INDEX(Familles!$D$2:$D$7,MATCH($C5,Familles!$A$2:$A$7,0))),"") -> Payant pour tous (gratuit -18 ans) | G5: =IFERROR(IF(INDEX(Familles!$E$2:$E$7,MATCH($C5,Familles!$A$2:$A$7,0))="","",INDEX(Familles!$E$2:$E$7,MATCH($C5,Familles!$A$2:$A$7,0))),"") | K5: à vérifier
A6: musee-cognacq-jay-musee-du-xviiie-siecle-de-la-ville-de-pari | B6: Musée Cognacq-Jay, musée du XVIIIe siècle de la ville de Paris | C6: paris_musees | D6: sûr | E6: =IFERROR(IF(INDEX(Familles!$C$2:$C$7,MATCH($C6,Familles!$A$2:$A$7,0))="","",INDEX(Familles!$C$2:$C$7,MATCH($C6,Familles!$A$2:$A$7,0))),"") -> Gratuit pour tous | F6: =IFERROR(IF(INDEX(Familles!$D$2:$D$7,MATCH($C6,Familles!$A$2:$A$7,0))="","",INDEX(Familles!$D$2:$D$7,MATCH($C6,Familles!$A$2:$A$7,0))),"") -> Payant pour tous (gratuit -18 ans) | G6: =IFERROR(IF(INDEX(Familles!$E$2:$E$7,MATCH($C6,Familles!$A$2:$A$7,0))="","",INDEX(Familles!$E$2:$E$7,MATCH($C6,Familles!$A$2:$A$7,0))),"") | K6: à vérifier
A7: musee-d-art-moderne-de-la-ville-de-paris | B7: Musée d'art moderne de la ville de Paris | C7: paris_musees | D7: sûr | E7: =IFERROR(IF(INDEX(Familles!$C$2:$C$7,MATCH($C7,Familles!$A$2:$A$7,0))="","",INDEX(Familles!$C$2:$C$7,MATCH($C7,Familles!$A$2:$A$7,0))),"") -> Gratuit pour tous | F7: =IFERROR(IF(INDEX(Familles!$D$2:$D$7,MATCH($C7,Familles!$A$2:$A$7,0))="","",INDEX(Familles!$D$2:$D$7,MATCH($C7,Familles!$A$2:$A$7,0))),"") -> Payant pour tous (gratuit -18 ans) | G7: =IFERROR(IF(INDEX(Familles!$E$2:$E$7,MATCH($C7,Familles!$A$2:$A$7,0))="","",INDEX(Familles!$E$2:$E$7,MATCH($C7,Familles!$A$2:$A$7,0))),"") | H7: https://www.mam.paris.fr/ | K7: à vérifier | N7: T1 | O7: billetterie-parismusees.paris.fr | P7: Reseau Paris Musees : les 14 sites partagent le MEME gabarit Drupal. Meme structure de menu (Votre visite / Expositions / Agenda), memes images sous /sites/default/files/styles/, meme balise og:image exploitable, et un /sitemap sur chaque site. UN SEUL crawler couvre les 14. Attention : le chemin exact de la page expos varie legerement d'un site a l'autre (/expositions/exposition-en-cours, /expositions/expositions-en-cours, /visiter/expositions/expositions-en-cours) : a confirmer site par site.
A8: musee-de-la-liberation-de-paris-musee-du-general-leclerc-mus | B8: Musée de la Libération de Paris - musée du général Leclerc - musée Jean Moulin | C8: paris_musees | D8: sûr | E8: =IFERROR(IF(INDEX(Familles!$C$2:$C$7,MATCH($C8,Familles!$A$2:$A$7,0))="","",INDEX(Familles!$C$2:$C$7,MATCH($C8,Familles!$A$2:$A$7,0))),"") -> Gratuit pour tous | F8: =IFERROR(IF(INDEX(Familles!$D$2:$D$7,MATCH($C8,Familles!$A$2:$A$7,0))="","",INDEX(Familles!$D$2:$D$7,MATCH($C8,Familles!$A$2:$A$7,0))),"") -> Payant pour tous (gratuit -18 ans) | G8: =IFERROR(IF(INDEX(Familles!$E$2:$E$7,MATCH($C8,Familles!$A$2:$A$7,0))="","",INDEX(Familles!$E$2:$E$7,MATCH($C8,Familles!$A$2:$A$7,0))),"") | K8: à vérifier
A9: musee-de-la-vie-romantique | B9: Musée de la vie romantique | C9: paris_musees | D9: sûr | E9: =IFERROR(IF(INDEX(Familles!$C$2:$C$7,MATCH($C9,Familles!$A$2:$A$7,0))="","",INDEX(Familles!$C$2:$C$7,MATCH($C9,Familles!$A$2:$A$7,0))),"") -> Gratuit pour tous | F9: =IFERROR(IF(INDEX(Familles!$D$2:$D$7,MATCH($C9,Familles!$A$2:$A$7,0))="","",INDEX(Familles!$D$2:$D$7,MATCH($C9,Familles!$A$2:$A$7,0))),"") -> Payant pour tous (gratuit -18 ans) | G9: =IFERROR(IF(INDEX(Familles!$E$2:$E$7,MATCH($C9,Familles!$A$2:$A$7,0))="","",INDEX(Familles!$E$2:$E$7,MATCH($C9,Familles!$A$2:$A$7,0))),"") | H9: https://museevieromantique.paris.fr/expositions/exposition-en-cours | I9: https://museevieromantique.paris.fr/votre-visite/informations-pratiques | K9: vérifié | L9: 2026-09-19 | N9: T1 | O9: billetterie-parismusees.paris.fr | P9: ROUVERT, les travaux sont termines. Reseau Paris Musees : les 14 sites partagent le MEME gabarit Drupal. Meme structure de menu (Votre visite / Expositions / Agenda), memes images sous /sites/default/files/styles/, meme balise og:image exploitable, et un /sitemap sur chaque site. UN SEUL crawler couvre les 14. Attention : le chemin exact de la page expos varie legerement d'un site a l'autre (/expositions/exposition-en-cours, /expositions/expositions-en-cours, /visiter/expositions/expositions-en-cours) : a confirmer site par site. | Q9: https://museevieromantique.paris.fr/sites/default/files/styles/metatag/public/images/2026-05/15%20mars%202026%40Mus%C3%A9e%20de%20la%20vie%20romantique-Paris%20Mus%C3%A9es-IP3%20PRESS%20BD002.JPG.webp | R9: https://museevieromantique.paris.fr/votre-visite/informations-pratiques
A10: musee-zadkine | B10: Musée Zadkine | C10: paris_musees | D10: sûr | E10: =IFERROR(IF(INDEX(Familles!$C$2:$C$7,MATCH($C10,Familles!$A$2:$A$7,0))="","",INDEX(Familles!$C$2:$C$7,MATCH($C10,Familles!$A$2:$A$7,0))),"") -> Gratuit pour tous | F10: =IFERROR(IF(INDEX(Familles!$D$2:$D$7,MATCH($C10,Familles!$A$2:$A$7,0))="","",INDEX(Familles!$D$2:$D$7,MATCH($C10,Familles!$A$2:$A$7,0))),"") -> Payant pour tous (gratuit -18 ans) | G10: =IFERROR(IF(INDEX(Familles!$E$2:$E$7,MATCH($C10,Familles!$A$2:$A$7,0))="","",INDEX(Familles!$E$2:$E$7,MATCH($C10,Familles!$A$2:$A$7,0))),"") | H10: A TROUVER (probablement zadkine.paris.fr) | K10: à vérifier | N10: T1 | O10: billetterie-parismusees.paris.fr | P10: Reseau Paris Musees : les 14 sites partagent le MEME gabarit Drupal. Meme structure de menu (Votre visite / Expositions / Agenda), memes images sous /sites/default/files/styles/, meme balise og:image exploitable, et un /sitemap sur chaque site. UN SEUL crawler couvre les 14. Attention : le chemin exact de la page expos varie legerement d'un site a l'autre (/expositions/exposition-en-cours, /expositions/expositions-en-cours, /visiter/expositions/expositions-en-cours) : a confirmer site par site.
A11: palais-galliera-musee-de-la-mode-et-de-la-ville-de-paris | B11: Palais Galliera, musée de la mode et de la ville de Paris | C11: paris_musees | D11: sûr | E11: =IFERROR(IF(INDEX(Familles!$C$2:$C$7,MATCH($C11,Familles!$A$2:$A$7,0))="","",INDEX(Familles!$C$2:$C$7,MATCH($C11,Familles!$A$2:$A$7,0))),"") -> Gratuit pour tous | F11: =IFERROR(IF(INDEX(Familles!$D$2:$D$7,MATCH($C11,Familles!$A$2:$A$7,0))="","",INDEX(Familles!$D$2:$D$7,MATCH($C11,Familles!$A$2:$A$7,0))),"") -> Payant pour tous (gratuit -18 ans) | G11: =IFERROR(IF(INDEX(Familles!$E$2:$E$7,MATCH($C11,Familles!$A$2:$A$7,0))="","",INDEX(Familles!$E$2:$E$7,MATCH($C11,Familles!$A$2:$A$7,0))),"") | H11: https://palaisgalliera.paris.fr/ | J11: EXCEPTION a la regle Paris Musees : le Palais Galliera n'a pas de collection permanente gratuite, tout est payant. A verifier sur leur site. | K11: à vérifier | N11: T1 | O11: billetterie-parismusees.paris.fr | P11: Reseau Paris Musees : les 14 sites partagent le MEME gabarit Drupal. Meme structure de menu (Votre visite / Expositions / Agenda), memes images sous /sites/default/files/styles/, meme balise og:image exploitable, et un /sitemap sur chaque site. UN SEUL crawler couvre les 14. Attention : le chemin exact de la page expos varie legerement d'un site a l'autre (/expositions/exposition-en-cours, /expositions/expositions-en-cours, /visiter/expositions/expositions-en-cours) : a confirmer site par site.
A12: petit-palais-musee-des-beaux-arts-de-la-ville-de-paris | B12: Petit Palais, musée des beaux-arts de la ville de Paris | C12: paris_musees | D12: sûr | E12: =IFERROR(IF(INDEX(Familles!$C$2:$C$7,MATCH($C12,Familles!$A$2:$A$7,0))="","",INDEX(Familles!$C$2:$C$7,MATCH($C12,Familles!$A$2:$A$7,0))),"") -> Gratuit pour tous | F12: =IFERROR(IF(INDEX(Familles!$D$2:$D$7,MATCH($C12,Familles!$A$2:$A$7,0))="","",INDEX(Familles!$D$2:$D$7,MATCH($C12,Familles!$A$2:$A$7,0))),"") -> Payant pour tous (gratuit -18 ans) | G12: =IFERROR(IF(INDEX(Familles!$E$2:$E$7,MATCH($C12,Familles!$A$2:$A$7,0))="","",INDEX(Familles!$E$2:$E$7,MATCH($C12,Familles!$A$2:$A$7,0))),"") | H12: https://www.petitpalais.paris.fr/ | K12: à vérifier | N12: T1 | O12: billetterie-parismusees.paris.fr | P12: Reseau Paris Musees : les 14 sites partagent le MEME gabarit Drupal. Meme structure de menu (Votre visite / Expositions / Agenda), memes images sous /sites/default/files/styles/, meme balise og:image exploitable, et un /sitemap sur chaque site. UN SEUL crawler couvre les 14. Attention : le chemin exact de la page expos varie legerement d'un site a l'autre (/expositions/exposition-en-cours, /expositions/expositions-en-cours, /visiter/expositions/expositions-en-cours) : a confirmer site par site.
A13: crypte-archeologique-de-l-ile-de-la-cite | B13: Crypte archéologique de l'Île de la Cité | C13: paris_musees | D13: à confirmer | E13: =IFERROR(IF(INDEX(Familles!$C$2:$C$7,MATCH($C13,Familles!$A$2:$A$7,0))="","",INDEX(Familles!$C$2:$C$7,MATCH($C13,Familles!$A$2:$A$7,0))),"") -> Gratuit pour tous | F13: =IFERROR(IF(INDEX(Familles!$D$2:$D$7,MATCH($C13,Familles!$A$2:$A$7,0))="","",INDEX(Familles!$D$2:$D$7,MATCH($C13,Familles!$A$2:$A$7,0))),"") -> Payant pour tous (gratuit -18 ans) | G13: =IFERROR(IF(INDEX(Familles!$E$2:$E$7,MATCH($C13,Familles!$A$2:$A$7,0))="","",INDEX(Familles!$E$2:$E$7,MATCH($C13,Familles!$A$2:$A$7,0))),"") | H13: https://www.crypte.paris.fr/ | J13: EXCEPTION a la regle Paris Musees : la Crypte est payante, comme les Catacombes. A verifier. | K13: à vérifier | M13: Géré par Paris Musées — confirmer | N13: T1 | O13: billetterie-parismusees.paris.fr | P13: Reseau Paris Musees : les 14 sites partagent le MEME gabarit Drupal. Meme structure de menu (Votre visite / Expositions / Agenda), memes images sous /sites/default/files/styles/, meme balise og:image exploitable, et un /sitemap sur chaque site. UN SEUL crawler couvre les 14. Attention : le chemin exact de la page expos varie legerement d'un site a l'autre (/expositions/exposition-en-cours, /expositions/expositions-en-cours, /visiter/expositions/expositions-en-cours) : a confirmer site par site.
A14: musee-du-louvre | B14: Musée du Louvre | C14: musee_national | D14: sûr | E14: =IFERROR(IF(INDEX(Familles!$C$2:$C$7,MATCH($C14,Familles!$A$2:$A$7,0))="","",INDEX(Familles!$C$2:$C$7,MATCH($C14,Familles!$A$2:$A$7,0))),"") -> Gratuit | F14: =IFERROR(IF(INDEX(Familles!$D$2:$D$7,MATCH($C14,Familles!$A$2:$A$7,0))="","",INDEX(Familles!$D$2:$D$7,MATCH($C14,Familles!$A$2:$A$7,0))),"") -> Variable selon l'établissement | G14: =IFERROR(IF(INDEX(Familles!$E$2:$E$7,MATCH($C14,Familles!$A$2:$A$7,0))="","",INDEX(Familles!$E$2:$E$7,MATCH($C14,Familles!$A$2:$A$7,0))),"") -> 26 | K14: à vérifier | M14: Nocturne du vendredi : vérifier le dispositif jeunes en cours
A15: musee-d-orsay | B15: Musée d'Orsay | C15: musee_national | D15: sûr | E15: =IFERROR(IF(INDEX(Familles!$C$2:$C$7,MATCH($C15,Familles!$A$2:$A$7,0))="","",INDEX(Familles!$C$2:$C$7,MATCH($C15,Familles!$A$2:$A$7,0))),"") -> Gratuit | F15: =IFERROR(IF(INDEX(Familles!$D$2:$D$7,MATCH($C15,Familles!$A$2:$A$7,0))="","",INDEX(Familles!$D$2:$D$7,MATCH($C15,Familles!$A$2:$A$7,0))),"") -> Variable selon l'établissement | G15: =IFERROR(IF(INDEX(Familles!$E$2:$E$7,MATCH($C15,Familles!$A$2:$A$7,0))="","",INDEX(Familles!$E$2:$E$7,MATCH($C15,Familles!$A$2:$A$7,0))),"") -> 26 | K15: à vérifier
A16: musee-de-l-orangerie-des-tuileries | B16: Musée de l'Orangerie des Tuileries | C16: musee_national | D16: sûr | E16: =IFERROR(IF(INDEX(Familles!$C$2:$C$7,MATCH($C16,Familles!$A$2:$A$7,0))="","",INDEX(Familles!$C$2:$C$7,MATCH($C16,Familles!$A$2:$A$7,0))),"") -> Gratuit | F16: =IFERROR(IF(INDEX(Familles!$D$2:$D$7,MATCH($C16,Familles!$A$2:$A$7,0))="","",INDEX(Familles!$D$2:$D$7,MATCH($C16,Familles!$A$2:$A$7,0))),"") -> Variable selon l'établissement | G16: =IFERROR(IF(INDEX(Familles!$E$2:$E$7,MATCH($C16,Familles!$A$2:$A$7,0))="","",INDEX(Familles!$E$2:$E$7,MATCH($C16,Familles!$A$2:$A$7,0))),"") -> 26 | K16: à vérifier | M16: Rattaché à Orsay
A17: musee-des-arts-asiatiques-guimet | B17: Musée des arts asiatiques Guimet | C17: musee_national | D17: sûr | E17: =IFERROR(IF(INDEX(Familles!$C$2:$C$7,MATCH($C17,Familles!$A$2:$A$7,0))="","",INDEX(Familles!$C$2:$C$7,MATCH($C17,Familles!$A$2:$A$7,0))),"") -> Gratuit | F17: =IFERROR(IF(INDEX(Familles!$D$2:$D$7,MATCH($C17,Familles!$A$2:$A$7,0))="","",INDEX(Familles!$D$2:$D$7,MATCH($C17,Familles!$A$2:$A$7,0))),"") -> Variable selon l'établissement | G17: =IFERROR(IF(INDEX(Familles!$E$2:$E$7,MATCH($C17,Familles!$A$2:$A$7,0))="","",INDEX(Familles!$E$2:$E$7,MATCH($C17,Familles!$A$2:$A$7,0))),"") -> 26 | K17: à vérifier
A18: musee-du-moyen-age-thermes-et-hotel-de-cluny | B18: Musée du Moyen Âge - thermes et hôtel de Cluny | C18: musee_national | D18: sûr | E18: =IFERROR(IF(INDEX(Familles!$C$2:$C$7,MATCH($C18,Familles!$A$2:$A$7,0))="","",INDEX(Familles!$C$2:$C$7,MATCH($C18,Familles!$A$2:$A$7,0))),"") -> Gratuit | F18: =IFERROR(IF(INDEX(Familles!$D$2:$D$7,MATCH($C18,Familles!$A$2:$A$7,0))="","",INDEX(Familles!$D$2:$D$7,MATCH($C18,Familles!$A$2:$A$7,0))),"") -> Variable selon l'établissement | G18: =IFERROR(IF(INDEX(Familles!$E$2:$E$7,MATCH($C18,Familles!$A$2:$A$7,0))="","",INDEX(Familles!$E$2:$E$7,MATCH($C18,Familles!$A$2:$A$7,0))),"") -> 26 | K18: à vérifier
A19: musee-du-quai-branly-jacques-chirac | B19: Musée du Quai Branly - Jacques Chirac | C19: musee_national | D19: sûr | E19: =IFERROR(IF(INDEX(Familles!$C$2:$C$7,MATCH($C19,Familles!$A$2:$A$7,0))="","",INDEX(Familles!$C$2:$C$7,MATCH($C19,Familles!$A$2:$A$7,0))),"") -> Gratuit | F19: =IFERROR(IF(INDEX(Familles!$D$2:$D$7,MATCH($C19,Familles!$A$2:$A$7,0))="","",INDEX(Familles!$D$2:$D$7,MATCH($C19,Familles!$A$2:$A$7,0))),"") -> Variable selon l'établissement | G19: =IFERROR(IF(INDEX(Familles!$E$2:$E$7,MATCH($C19,Familles!$A$2:$A$7,0))="","",INDEX(Familles!$E$2:$E$7,MATCH($C19,Familles!$A$2:$A$7,0))),"") -> 26 | K19: à vérifier
A20: musee-eugene-delacroix | B20: Musée Eugène Delacroix | C20: musee_national | D20: sûr | E20: =IFERROR(IF(INDEX(Familles!$C$2:$C$7,MATCH($C20,Familles!$A$2:$A$7,0))="","",INDEX(Familles!$C$2:$C$7,MATCH($C20,Familles!$A$2:$A$7,0))),"") -> Gratuit | F20: =IFERROR(IF(INDEX(Familles!$D$2:$D$7,MATCH($C20,Familles!$A$2:$A$7,0))="","",INDEX(Familles!$D$2:$D$7,MATCH($C20,Familles!$A$2:$A$7,0))),"") -> Variable selon l'établissement | G20: =IFERROR(IF(INDEX(Familles!$E$2:$E$7,MATCH($C20,Familles!$A$2:$A$7,0))="","",INDEX(Familles!$E$2:$E$7,MATCH($C20,Familles!$A$2:$A$7,0))),"") -> 26 | K20: à vérifier | M20: Rattaché au Louvre
A21: musee-gustave-moreau | B21: Musée Gustave Moreau | C21: musee_national | D21: sûr | E21: =IFERROR(IF(INDEX(Familles!$C$2:$C$7,MATCH($C21,Familles!$A$2:$A$7,0))="","",INDEX(Familles!$C$2:$C$7,MATCH($C21,Familles!$A$2:$A$7,0))),"") -> Gratuit | F21: =IFERROR(IF(INDEX(Familles!$D$2:$D$7,MATCH($C21,Familles!$A$2:$A$7,0))="","",INDEX(Familles!$D$2:$D$7,MATCH($C21,Familles!$A$2:$A$7,0))),"") -> Variable selon l'établissement | G21: =IFERROR(IF(INDEX(Familles!$E$2:$E$7,MATCH($C21,Familles!$A$2:$A$7,0))="","",INDEX(Familles!$E$2:$E$7,MATCH($C21,Familles!$A$2:$A$7,0))),"") -> 26 | K21: à vérifier
A22: musee-hebert | B22: Musée Hébert | C22: musee_national | D22: à confirmer | E22: =IFERROR(IF(INDEX(Familles!$C$2:$C$7,MATCH($C22,Familles!$A$2:$A$7,0))="","",INDEX(Familles!$C$2:$C$7,MATCH($C22,Familles!$A$2:$A$7,0))),"") -> Gratuit | F22: =IFERROR(IF(INDEX(Familles!$D$2:$D$7,MATCH($C22,Familles!$A$2:$A$7,0))="","",INDEX(Familles!$D$2:$D$7,MATCH($C22,Familles!$A$2:$A$7,0))),"") -> Variable selon l'établissement | G22: =IFERROR(IF(INDEX(Familles!$E$2:$E$7,MATCH($C22,Familles!$A$2:$A$7,0))="","",INDEX(Familles!$E$2:$E$7,MATCH($C22,Familles!$A$2:$A$7,0))),"") -> 26 | K22: à vérifier | M22: Le site parisien (rue du Cherche-Midi) est fermé de longue date — vérifier, sinon passer en « hors périmètre »
A23: musee-jean-jacques-henner | B23: Musée Jean-Jacques Henner | C23: musee_national | D23: sûr | E23: =IFERROR(IF(INDEX(Familles!$C$2:$C$7,MATCH($C23,Familles!$A$2:$A$7,0))="","",INDEX(Familles!$C$2:$C$7,MATCH($C23,Familles!$A$2:$A$7,0))),"") -> Gratuit | F23: =IFERROR(IF(INDEX(Familles!$D$2:$D$7,MATCH($C23,Familles!$A$2:$A$7,0))="","",INDEX(Familles!$D$2:$D$7,MATCH($C23,Familles!$A$2:$A$7,0))),"") -> Variable selon l'établissement | G23: =IFERROR(IF(INDEX(Familles!$E$2:$E$7,MATCH($C23,Familles!$A$2:$A$7,0))="","",INDEX(Familles!$E$2:$E$7,MATCH($C23,Familles!$A$2:$A$7,0))),"") -> 26 | K23: à vérifier
A24: musee-picasso | B24: Musée Picasso | C24: musee_national | D24: sûr | E24: =IFERROR(IF(INDEX(Familles!$C$2:$C$7,MATCH($C24,Familles!$A$2:$A$7,0))="","",INDEX(Familles!$C$2:$C$7,MATCH($C24,Familles!$A$2:$A$7,0))),"") -> Gratuit | F24: =IFERROR(IF(INDEX(Familles!$D$2:$D$7,MATCH($C24,Familles!$A$2:$A$7,0))="","",INDEX(Familles!$D$2:$D$7,MATCH($C24,Familles!$A$2:$A$7,0))),"") -> Variable selon l'établissement | G24: =IFERROR(IF(INDEX(Familles!$E$2:$E$7,MATCH($C24,Familles!$A$2:$A$7,0))="","",INDEX(Familles!$E$2:$E$7,MATCH($C24,Familles!$A$2:$A$7,0))),"") -> 26 | K24: à vérifier
A25: musee-rodin | B25: Musée Rodin | C25: musee_national | D25: sûr | E25: =IFERROR(IF(INDEX(Familles!$C$2:$C$7,MATCH($C25,Familles!$A$2:$A$7,0))="","",INDEX(Familles!$C$2:$C$7,MATCH($C25,Familles!$A$2:$A$7,0))),"") -> Gratuit | F25: =IFERROR(IF(INDEX(Familles!$D$2:$D$7,MATCH($C25,Familles!$A$2:$A$7,0))="","",INDEX(Familles!$D$2:$D$7,MATCH($C25,Familles!$A$2:$A$7,0))),"") -> Variable selon l'établissement | G25: =IFERROR(IF(INDEX(Familles!$E$2:$E$7,MATCH($C25,Familles!$A$2:$A$7,0))="","",INDEX(Familles!$E$2:$E$7,MATCH($C25,Familles!$A$2:$A$7,0))),"") -> 26 | K25: à vérifier
A26: musee-national-d-art-moderne-centre-national-d-art-et-de-cul | B26: Musée national d'art moderne (centre national d'art et de culture Georges Pompidou) | C26: musee_national | D26: sûr | E26: =IFERROR(IF(INDEX(Familles!$C$2:$C$7,MATCH($C26,Familles!$A$2:$A$7,0))="","",INDEX(Familles!$C$2:$C$7,MATCH($C26,Familles!$A$2:$A$7,0))),"") -> Gratuit | F26: =IFERROR(IF(INDEX(Familles!$D$2:$D$7,MATCH($C26,Familles!$A$2:$A$7,0))="","",INDEX(Familles!$D$2:$D$7,MATCH($C26,Familles!$A$2:$A$7,0))),"") -> Variable selon l'établissement | G26: =IFERROR(IF(INDEX(Familles!$E$2:$E$7,MATCH($C26,Familles!$A$2:$A$7,0))="","",INDEX(Familles!$E$2:$E$7,MATCH($C26,Familles!$A$2:$A$7,0))),"") -> 26 | K26: à vérifier | M26: ATTENTION : Centre Pompidou fermé pour travaux — vérifier le statut et les sites hors-les-murs
A27: musee-national-de-l-histoire-et-des-cultures-de-l-immigratio | B27: Musée national de l'histoire et des cultures de l'immigration | C27: musee_national | D27: sûr | E27: =IFERROR(IF(INDEX(Familles!$C$2:$C$7,MATCH($C27,Familles!$A$2:$A$7,0))="","",INDEX(Familles!$C$2:$C$7,MATCH($C27,Familles!$A$2:$A$7,0))),"") -> Gratuit | F27: =IFERROR(IF(INDEX(Familles!$D$2:$D$7,MATCH($C27,Familles!$A$2:$A$7,0))="","",INDEX(Familles!$D$2:$D$7,MATCH($C27,Familles!$A$2:$A$7,0))),"") -> Variable selon l'établissement | G27: =IFERROR(IF(INDEX(Familles!$E$2:$E$7,MATCH($C27,Familles!$A$2:$A$7,0))="","",INDEX(Familles!$E$2:$E$7,MATCH($C27,Familles!$A$2:$A$7,0))),"") -> 26 | K27: à vérifier | M27: Palais de la Porte Dorée
A28: musee-national-de-la-marine | B28: Musée national de la marine | C28: musee_national | D28: sûr | E28: =IFERROR(IF(INDEX(Familles!$C$2:$C$7,MATCH($C28,Familles!$A$2:$A$7,0))="","",INDEX(Familles!$C$2:$C$7,MATCH($C28,Familles!$A$2:$A$7,0))),"") -> Gratuit | F28: =IFERROR(IF(INDEX(Familles!$D$2:$D$7,MATCH($C28,Familles!$A$2:$A$7,0))="","",INDEX(Familles!$D$2:$D$7,MATCH($C28,Familles!$A$2:$A$7,0))),"") -> Variable selon l'établissement | G28: =IFERROR(IF(INDEX(Familles!$E$2:$E$7,MATCH($C28,Familles!$A$2:$A$7,0))="","",INDEX(Familles!$E$2:$E$7,MATCH($C28,Familles!$A$2:$A$7,0))),"") -> 26 | K28: à vérifier
A29: musee-national-de-la-legion-d-honneur-et-des-ordres-de-cheva | B29: Musée national de la Légion d'honneur et des ordres de chevalerie | C29: musee_national | D29: à confirmer | E29: =IFERROR(IF(INDEX(Familles!$C$2:$C$7,MATCH($C29,Familles!$A$2:$A$7,0))="","",INDEX(Familles!$C$2:$C$7,MATCH($C29,Familles!$A$2:$A$7,0))),"") -> Gratuit | F29: =IFERROR(IF(INDEX(Familles!$D$2:$D$7,MATCH($C29,Familles!$A$2:$A$7,0))="","",INDEX(Familles!$D$2:$D$7,MATCH($C29,Familles!$A$2:$A$7,0))),"") -> Variable selon l'établissement | G29: =IFERROR(IF(INDEX(Familles!$E$2:$E$7,MATCH($C29,Familles!$A$2:$A$7,0))="","",INDEX(Familles!$E$2:$E$7,MATCH($C29,Familles!$A$2:$A$7,0))),"") -> 26 | K29: à vérifier | M29: Souvent annoncé gratuit pour tous — à vérifier, exception probable
A30: musee-des-monuments-francais | B30: Musée des monuments français | C30: musee_national | D30: à confirmer | E30: =IFERROR(IF(INDEX(Familles!$C$2:$C$7,MATCH($C30,Familles!$A$2:$A$7,0))="","",INDEX(Familles!$C$2:$C$7,MATCH($C30,Familles!$A$2:$A$7,0))),"") -> Gratuit | F30: =IFERROR(IF(INDEX(Familles!$D$2:$D$7,MATCH($C30,Familles!$A$2:$A$7,0))="","",INDEX(Familles!$D$2:$D$7,MATCH($C30,Familles!$A$2:$A$7,0))),"") -> Variable selon l'établissement | G30: =IFERROR(IF(INDEX(Familles!$E$2:$E$7,MATCH($C30,Familles!$A$2:$A$7,0))="","",INDEX(Familles!$E$2:$E$7,MATCH($C30,Familles!$A$2:$A$7,0))),"") -> 26 | K30: à vérifier | M30: Cité de l'architecture et du patrimoine
A31: musee-des-plans-reliefs | B31: Musée des Plans-reliefs | C31: musee_national | D31: à confirmer | E31: =IFERROR(IF(INDEX(Familles!$C$2:$C$7,MATCH($C31,Familles!$A$2:$A$7,0))="","",INDEX(Familles!$C$2:$C$7,MATCH($C31,Familles!$A$2:$A$7,0))),"") -> Gratuit | F31: =IFERROR(IF(INDEX(Familles!$D$2:$D$7,MATCH($C31,Familles!$A$2:$A$7,0))="","",INDEX(Familles!$D$2:$D$7,MATCH($C31,Familles!$A$2:$A$7,0))),"") -> Variable selon l'établissement | G31: =IFERROR(IF(INDEX(Familles!$E$2:$E$7,MATCH($C31,Familles!$A$2:$A$7,0))="","",INDEX(Familles!$E$2:$E$7,MATCH($C31,Familles!$A$2:$A$7,0))),"") -> 26 | K31: à vérifier | M31: Situé aux Invalides, billet couplé musée de l'Armée
A32: musee-d-ennery | B32: Musée d'Ennery | C32: musee_national | D32: à confirmer | E32: =IFERROR(IF(INDEX(Familles!$C$2:$C$7,MATCH($C32,Familles!$A$2:$A$7,0))="","",INDEX(Familles!$C$2:$C$7,MATCH($C32,Familles!$A$2:$A$7,0))),"") -> Gratuit | F32: =IFERROR(IF(INDEX(Familles!$D$2:$D$7,MATCH($C32,Familles!$A$2:$A$7,0))="","",INDEX(Familles!$D$2:$D$7,MATCH($C32,Familles!$A$2:$A$7,0))),"") -> Variable selon l'établissement | G32: =IFERROR(IF(INDEX(Familles!$E$2:$E$7,MATCH($C32,Familles!$A$2:$A$7,0))="","",INDEX(Familles!$E$2:$E$7,MATCH($C32,Familles!$A$2:$A$7,0))),"") -> 26 | K32: à vérifier | M32: Rattaché à Guimet — ouverture très limitée, vérifier s'il est ouvert
A33: musee-de-l-ecole-nationale-superieure-des-beaux-arts | B33: Musée de l'Ecole nationale supérieure des beaux-arts | C33: autre_public | D33: à confirmer | E33: =IFERROR(IF(INDEX(Familles!$C$2:$C$7,MATCH($C33,Familles!$A$2:$A$7,0))="","",INDEX(Familles!$C$2:$C$7,MATCH($C33,Familles!$A$2:$A$7,0))),"") -> À VÉRIFIER | F33: =IFERROR(IF(INDEX(Familles!$D$2:$D$7,MATCH($C33,Familles!$A$2:$A$7,0))="","",INDEX(Familles!$D$2:$D$7,MATCH($C33,Familles!$A$2:$A$7,0))),"") -> À VÉRIFIER | G33: =IFERROR(IF(INDEX(Familles!$E$2:$E$7,MATCH($C33,Familles!$A$2:$A$7,0))="","",INDEX(Familles!$E$2:$E$7,MATCH($C33,Familles!$A$2:$A$7,0))),"") | K33: à vérifier | M33: ENSBA, ouvertures ponctuelles
A34: sainte-chapelle | B34: Sainte-Chapelle | C34: cmn | D34: sûr | E34: =IFERROR(IF(INDEX(Familles!$C$2:$C$7,MATCH($C34,Familles!$A$2:$A$7,0))="","",INDEX(Familles!$C$2:$C$7,MATCH($C34,Familles!$A$2:$A$7,0))),"") -> Gratuit | F34: =IFERROR(IF(INDEX(Familles!$D$2:$D$7,MATCH($C34,Familles!$A$2:$A$7,0))="","",INDEX(Familles!$D$2:$D$7,MATCH($C34,Familles!$A$2:$A$7,0))),"") -> Généralement inclus dans le billet | G34: =IFERROR(IF(INDEX(Familles!$E$2:$E$7,MATCH($C34,Familles!$A$2:$A$7,0))="","",INDEX(Familles!$E$2:$E$7,MATCH($C34,Familles!$A$2:$A$7,0))),"") -> 26 | K34: à vérifier
A35: conciergerie | B35: Conciergerie | C35: cmn | D35: sûr | E35: =IFERROR(IF(INDEX(Familles!$C$2:$C$7,MATCH($C35,Familles!$A$2:$A$7,0))="","",INDEX(Familles!$C$2:$C$7,MATCH($C35,Familles!$A$2:$A$7,0))),"") -> Gratuit | F35: =IFERROR(IF(INDEX(Familles!$D$2:$D$7,MATCH($C35,Familles!$A$2:$A$7,0))="","",INDEX(Familles!$D$2:$D$7,MATCH($C35,Familles!$A$2:$A$7,0))),"") -> Généralement inclus dans le billet | G35: =IFERROR(IF(INDEX(Familles!$E$2:$E$7,MATCH($C35,Familles!$A$2:$A$7,0))="","",INDEX(Familles!$E$2:$E$7,MATCH($C35,Familles!$A$2:$A$7,0))),"") -> 26 | K35: à vérifier
A36: arc-de-triomphe | B36: Arc de Triomphe | C36: cmn | D36: sûr | E36: =IFERROR(IF(INDEX(Familles!$C$2:$C$7,MATCH($C36,Familles!$A$2:$A$7,0))="","",INDEX(Familles!$C$2:$C$7,MATCH($C36,Familles!$A$2:$A$7,0))),"") -> Gratuit | F36: =IFERROR(IF(INDEX(Familles!$D$2:$D$7,MATCH($C36,Familles!$A$2:$A$7,0))="","",INDEX(Familles!$D$2:$D$7,MATCH($C36,Familles!$A$2:$A$7,0))),"") -> Généralement inclus dans le billet | G36: =IFERROR(IF(INDEX(Familles!$E$2:$E$7,MATCH($C36,Familles!$A$2:$A$7,0))="","",INDEX(Familles!$E$2:$E$7,MATCH($C36,Familles!$A$2:$A$7,0))),"") -> 26 | K36: à vérifier
A37: pantheon | B37: Panthéon | C37: cmn | D37: sûr | E37: =IFERROR(IF(INDEX(Familles!$C$2:$C$7,MATCH($C37,Familles!$A$2:$A$7,0))="","",INDEX(Familles!$C$2:$C$7,MATCH($C37,Familles!$A$2:$A$7,0))),"") -> Gratuit | F37: =IFERROR(IF(INDEX(Familles!$D$2:$D$7,MATCH($C37,Familles!$A$2:$A$7,0))="","",INDEX(Familles!$D$2:$D$7,MATCH($C37,Familles!$A$2:$A$7,0))),"") -> Généralement inclus dans le billet | G37: =IFERROR(IF(INDEX(Familles!$E$2:$E$7,MATCH($C37,Familles!$A$2:$A$7,0))="","",INDEX(Familles!$E$2:$E$7,MATCH($C37,Familles!$A$2:$A$7,0))),"") -> 26 | K37: à vérifier
A38: musee-de-l-armee | B38: Musée de l'armée | C38: militaire | D38: sûr | E38: =IFERROR(IF(INDEX(Familles!$C$2:$C$7,MATCH($C38,Familles!$A$2:$A$7,0))="","",INDEX(Familles!$C$2:$C$7,MATCH($C38,Familles!$A$2:$A$7,0))),"") -> À VÉRIFIER | F38: =IFERROR(IF(INDEX(Familles!$D$2:$D$7,MATCH($C38,Familles!$A$2:$A$7,0))="","",INDEX(Familles!$D$2:$D$7,MATCH($C38,Familles!$A$2:$A$7,0))),"") -> À VÉRIFIER | G38: =IFERROR(IF(INDEX(Familles!$E$2:$E$7,MATCH($C38,Familles!$A$2:$A$7,0))="","",INDEX(Familles!$E$2:$E$7,MATCH($C38,Familles!$A$2:$A$7,0))),"") | K38: à vérifier | M38: Invalides
A39: musee-du-service-de-sante-des-armees-du-val-de-grace | B39: Musée du service de santé des armées du Val-de-Grâce | C39: militaire | D39: à confirmer | E39: =IFERROR(IF(INDEX(Familles!$C$2:$C$7,MATCH($C39,Familles!$A$2:$A$7,0))="","",INDEX(Familles!$C$2:$C$7,MATCH($C39,Familles!$A$2:$A$7,0))),"") -> À VÉRIFIER | F39: =IFERROR(IF(INDEX(Familles!$D$2:$D$7,MATCH($C39,Familles!$A$2:$A$7,0))="","",INDEX(Familles!$D$2:$D$7,MATCH($C39,Familles!$A$2:$A$7,0))),"") -> À VÉRIFIER | G39: =IFERROR(IF(INDEX(Familles!$E$2:$E$7,MATCH($C39,Familles!$A$2:$A$7,0))="","",INDEX(Familles!$E$2:$E$7,MATCH($C39,Familles!$A$2:$A$7,0))),"") | K39: à vérifier | M39: Vérifier s'il est ouvert au public
A40: musee-des-arts-decoratifs-union-centrale-des-arts-decoratifs | B40: Musée des arts décoratifs (Union centrale des arts décoratifs) | C40: prive_assoc | D40: sûr | E40: =IFERROR(IF(INDEX(Familles!$C$2:$C$7,MATCH($C40,Familles!$A$2:$A$7,0))="","",INDEX(Familles!$C$2:$C$7,MATCH($C40,Familles!$A$2:$A$7,0))),"") -> À VÉRIFIER | F40: =IFERROR(IF(INDEX(Familles!$D$2:$D$7,MATCH($C40,Familles!$A$2:$A$7,0))="","",INDEX(Familles!$D$2:$D$7,MATCH($C40,Familles!$A$2:$A$7,0))),"") -> À VÉRIFIER | G40: =IFERROR(IF(INDEX(Familles!$E$2:$E$7,MATCH($C40,Familles!$A$2:$A$7,0))="","",INDEX(Familles!$E$2:$E$7,MATCH($C40,Familles!$A$2:$A$7,0))),"") | H40: https://madparis.fr/Expositions-en-cours-104 | I40: https://madparis.fr/Tarifs-et-gratuites | K40: vérifié | L40: 2026-09-19 | M40: MAD — association loi 1901 | N40: T1 | O40: billetterie.madparis.fr | P40: SPIP. ATTENTION : /Expositions-en-cours-104 renvoie une detection de bot. Utiliser le flux RSS https://madparis.fr/?id_rubrique=1&page=backend (SPIP expose un flux par rubrique via ?id_rubrique=N&page=backend). Le flux melange expos et ateliers enfants : filtrer. Titre reel dans l'ancre rel='directory', pas dans <title>. Images en lazy-load (placeholder rien.gif) : les vraies sont sous /local/cache-responsive/. | Q40: https://madparis.fr/local/cache-gd2/76/01f25b5d5c55eb7553fae2870d6f6d.jpg | R40: https://madparis.fr/Horaires-7
...

Sheet Tarifs
A1: lieu_id | B1: portee | C1: regime | D1: audience | E1: prix | F1: plein_tarif | G1: recurrence | H1: justificatif | I1: source_url | J1: verifie_le | K1: verifie_par
A2: fondation-cartier-pour-l-art-contemporain | B2: temporaire | C2: reduit | D2: moins_30 | E2: 10 | F2: 15 | G2: toujours | H2: Pièce d'identité | I2: https://www.fondationcartier.com/informations-pratiques (PDF conditions) | J2: 2026-09-19 | K2: claude
A3: fondation-cartier-pour-l-art-contemporain | B3: temporaire | C3: reduit | D3: etudiant_art | E3: 10 | F3: 15 | G3: toujours | H3: Attestation de scolarité mentionnant la matière (art, conservatoire) | I3: https://www.fondationcartier.com/informations-pratiques (PDF conditions) | J3: 2026-09-19 | K3: claude
A4: fondation-cartier-pour-l-art-contemporain | B4: temporaire | C4: reduit | D4: demandeur_emploi | E4: 10 | F4: 15 | G4: toujours | H4: Justificatif de moins de 3 mois | I4: https://www.fondationcartier.com/informations-pratiques (PDF conditions) | J4: 2026-09-19 | K4: claude
A5: fondation-cartier-pour-l-art-contemporain | B5: temporaire | C5: reduit | D5: enseignant | E5: 10 | F5: 15 | G5: toujours | H5: Pass Éducation en cours de validité | I5: https://www.fondationcartier.com/informations-pratiques (PDF conditions) | J5: 2026-09-19 | K5: claude
A6: fondation-cartier-pour-l-art-contemporain | B6: temporaire | C6: gratuit | D6: moins_18 | E6: 0 | F6: 15 | G6: toujours | H6: Pièce d'identité | I6: https://www.fondationcartier.com/informations-pratiques (PDF conditions) | J6: 2026-09-19 | K6: claude
A7: fondation-cartier-pour-l-art-contemporain | B7: temporaire | C7: gratuit | D7: minima_sociaux | E7: 0 | F7: 15 | G7: toujours | H7: Justificatif de moins de 3 mois | I7: https://www.fondationcartier.com/informations-pratiques (PDF conditions) | J7: 2026-09-19 | K7: claude
A8: fondation-cartier-pour-l-art-contemporain | B8: temporaire | C8: gratuit | D8: demandeur_asile | E8: 0 | F8: 15 | G8: toujours | H8: Attestation de demande d'asile ou carte de séjour « réfugié » | I8: https://www.fondationcartier.com/informations-pratiques (PDF conditions) | J8: 2026-09-19 | K8: claude
A9: fondation-cartier-pour-l-art-contemporain | B9: temporaire | C9: gratuit | D9: handicap | E9: 0 | F9: 15 | G9: toujours | H9: Carte MDPH, accompagnateur inclus | I9: https://www.fondationcartier.com/informations-pratiques (PDF conditions) | J9: 2026-09-19 | K9: claude
A10: fondation-cartier-pour-l-art-contemporain | B10: temporaire | C10: gratuit | D10: enseignant_arts_visuels | E10: 0 | F10: 15 | G10: toujours | H10: Attestation professionnelle ou certificat d'exercice | I10: https://www.fondationcartier.com/informations-pratiques (PDF conditions) | J10: 2026-09-19 | K10: claude
A11: fondation-cartier-pour-l-art-contemporain | B11: temporaire | C11: gratuit | D11: journaliste | E11: 0 | F11: 15 | G11: toujours | H11: Carte de presse | I11: https://www.fondationcartier.com/informations-pratiques (PDF conditions) | J11: 2026-09-19 | K11: claude
A12: fondation-cartier-pour-l-art-contemporain | B12: temporaire | C12: abonnement | D12: 18_29_ans | E12: 20 | F12: 15 | G12: annuel | H12: Adhésion « SOUVENT -30 » : accès illimité 1 an, pièce d'identité | I12: https://www.fondationcartier.com/informations-pratiques (PDF conditions) | J12: 2026-09-19 | K12: claude
A13: bourse-de-commerce-pinault-collection | B13: temporaire | C13: reduit | D13: moins_26 | E13: 10 | F13: 15 | G13: toujours | H13: Pièce d'identité (18-26 ans) | I13: https://www.pinaultcollection.com/fr/boursedecommerce/infos-pratiques | J13: 2026-09-19 | K13: claude
... A68: musee-de-la-vie-romantique | B68: permanent | C68: gratuit | D68: tous | E68: 0 | F68: 0 | G68: toujours | H68: Acces aux collections gratuit pour tout le monde, sans condition | I68: https://museevieromantique.paris.fr/votre-visite/informations-pratiques | J68: 2026-09-19 | K68: claude
A69: musee-de-la-vie-romantique | B69: temporaire | C69: reduit | D69: tous | G69: toujours | H69: Expositions temporaires payantes. Grille de tarifs a recuperer sur la page infos pratiques | I69: https://museevieromantique.paris.fr/votre-visite/informations-pratiques | J69: 2026-09-19 | K69: claude
A71: Une ligne = un droit d'accès. Un lieu peut en avoir 10.
A72: audience : tous | moins_18 | moins_26 | moins_26_ue | moins_30 | etudiant | etudiant_art | demandeur_emploi | minima_sociaux | enseignant | handicap | journaliste | demandeur_asile
A73: regime : gratuit | reduit | abonnement · recurrence : toujours | 1er_dimanche | nocturne_<jour> | apres_16h | <période datée>

Sheet Expositions
A1: lieu_id | B1: titre | C1: portee | D1: date_debut | E1: date_fin | F1: description | G1: url | H1: image_url | I1: statut | J1: source | K1: verifie_le | L1: verifie_par
A2: fondation-cartier-pour-l-art-contemporain | B2: Ibrahim Mahama. Le Temps des récoltes | C2: temporaire | D2: 2026-10-22 | E2: 2027-02-28 | F2: Exposition consacrée à l'artiste ghanéen Ibrahim Mahama et à ses compagnons, dans les nouveaux espaces du Palais-Royal. | G2: https://www.fondationcartier.com/programme/exposition/le-temps-des-recoltes-ibrahim-mahama | H2: https://www.fondationcartier.com/img/26caea61-f211-4a7c-9173-b0ca76b7961d/le-temps-des-recoltes-ibrahim-mahama-2025-kv.jpg | I2: complet | J2: site officiel | K2: 2026-09-19 | L2: claude
A3: fondation-cartier-pour-l-art-contemporain | B3: Raymond Hains : l'œuvre en chantier. Du Grand Louvre aux 3 Cartier | C3: temporaire | D3: 2026-06-09 | E3: 2026-10-26 | F3: Parcours consacré à Raymond Hains, présenté place du Palais-Royal. | G3: https://www.fondationcartier.com/programme/exposition/raymond-hains-l-oeuvre-en-chantier-du-grand-louvre-aux-3-cartier-place-palais-royal | H3: https://www.fondationcartier.com/img/2fbc6ff8-7a4a-4c59-b321-b7351b8a6691/sans-titre-1994-raymond-hains.jpg | I3: complet | J3: site officiel | K3: 2026-09-19 | L3: claude
A4: bourse-de-commerce-pinault-collection | B4: Remember Me | C4: temporaire | D4: 2026-10-07 | F4: Exposition en préparation pendant la période « musée en mouvement » (26 août au 5 octobre). Dates de fin à confirmer. | G4: https://www.pinaultcollection.com/fr/boursedecommerce/programme | I4: dates_a_confirmer | J4: site officiel | K4: 2026-09-19 | L4: claude
A5: musee-des-arts-decoratifs-union-centrale-des-arts-decoratifs | B5: Collections permanentes. Arts décoratifs, bijoux, design | C5: permanent | F5: Plus d'un million d'œuvres présentées sur sept étages, du Moyen Âge à nos jours. Audioguide inclus dans le billet. | G5: https://madparis.fr/Collections-permanentes-Arts-decoratifs-Design-Bijoux | H5: LOGO_MUSEE | I5: image_a_recuperer | J5: site officiel | K5: 2026-09-19 | L5: claude
A6: musee-des-arts-decoratifs-union-centrale-des-arts-decoratifs | B6: Une journée au XVIIIe siècle, chronique d'un hôtel particulier | C6: temporaire | D6: 2026-02-18 | E6: 2026-10-04 | G6: https://madparis.fr/Une-journee-au-XVIIIe-siecle-chronique-d-un-hotel-particulier-10157 | I6: image_a_recuperer | J6: site officiel | K6: 2026-09-19 | L6: claude
A7: musee-des-arts-decoratifs-union-centrale-des-arts-decoratifs | B7: La Mode en majesté. Haute couture et tradition à la cour de Thaïlande | C7: temporaire | D7: 2026-05-13 | E7: 2026-11-01 | G7: https://madparis.fr/La-Mode-en-majeste-Haute-couture-et-tradition-a-la-cour-de-Thailande-10206 | I7: image_a_recuperer | J7: site officiel | K7: 2026-09-19 | L7: claude
A8: musee-des-arts-decoratifs-union-centrale-des-arts-decoratifs | B8: Paris > Kyoto > Paris. Quatre designers de retour du Japon | C8: temporaire | D8: 2026-09-10 | E8: 2027-01-31 | F8: Les œuvres réunies rapportent toutes quelque chose du Japon sans jamais le contrefaire. Nina Fradet, Tony Jouanneau, Felipe Ribon et Marion Vidal convoquent la biologie, l'art, l'architecture et la mode. | G8: https://madparis.fr/Paris-Kyoto-Paris-Quatre-designers-de-retour-du-Japon | I8: dates_a_confirmer | J8: site officiel | K8: 2026-09-19 | L8: claude
A9: musee-des-arts-decoratifs-union-centrale-des-arts-decoratifs | B9: Look ! 40 ans de mode au musée | C9: temporaire | D9: 2026-09-30 | E9: 2027-04-04 | F9: Immersion dans les coulisses du musée : documenter, conditionner, restaurer et mannequiner un patrimoine de mode destiné aux générations futures. Fonds de l'Union française des Arts du Costume. | G9: https://madparis.fr/Look-40-ans-de-mode-au-musee-10263 | I9: dates_a_confirmer | J9: site officiel | K9: 2026-09-19 | L9: claude
A10: musee-des-arts-decoratifs-union-centrale-des-arts-decoratifs | B10: Marion Delarue. Pierre, plume, ciseaux ! | C10: temporaire | D10: 2026-10-06 | F10: Exposition-focus. Ornements en plume, nacre, porcelaine, verre et laque ; recherche autour de la technique chinoise du tian-ts'ui. | G10: https://madparis.fr/exposition-focus-marion-delarue | I10: dates_a_confirmer | J10: site officiel | K10: 2026-09-19 | L10: claude
A11: musee-des-arts-decoratifs-union-centrale-des-arts-decoratifs | B11: Rafael Pavarotti, photographe | C11: temporaire | D11: 2026-10-02 | F11: Le photographe de mode brésilien, passé par Rio, São Paulo et Londres avant Paris, publié dans Vogue, i-D et le New York Times. | G11: https://madparis.fr/Rafael-Pavarotti-photographe | I11: dates_a_confirmer | J11: site officiel | K11: 2026-09-19 | L11: claude
A12: musee-des-arts-decoratifs-union-centrale-des-arts-decoratifs | B12: Le monde de Viktor&Rolf. 30 ans de haute couture | C12: temporaire | D12: 2027-01-28 | F12: Depuis le début des années 1990, Viktor&Rolf conçoivent leurs collections comme des propositions artistiques explorant l'identité, la représentation et la transformation. | G12: https://madparis.fr/Le-monde-de-Viktor-Rolf-30-ans-de-haute-couture | I12: dates_a_confirmer | J12: site officiel | K12: 2026-09-19 | L12: claude
A13: musee-nissim-de-camondo-union-centrale-des-arts-decoratifs | B13: Collections permanentes du musée Nissim de Camondo | C13: permanent | F13: Hôtel particulier en bordure du parc Monceau, conservé dans son état d'origine, collection d'arts décoratifs du XVIIIe siècle. | G13: https://madparis.fr/Musee-Nissim-de-Camondo-125 | H13: LOGO_MUSEE | I13: image_a_recuperer | J13: site officiel | K13: 2026-09-19 | L13: claude
A14: musee-d-art-et-d-histoire-du-judaisme | B14: Parcours permanent | C14: permanent | F14: Deux mille ans de presence juive en France, replacee dans l'histoire du judaisme. Objets de culte, manuscrits, textiles et peintres de l'Ecole de Paris. Audioguide inclus. | G14: https://www.mahj.org/fr/parcours-permanent | H14: LOGO_MUSEE | I14: image_a_recuperer | J14: site officiel | K14: 2026-09-19 | L14: claude
A15: musee-d-art-et-d-histoire-du-judaisme | B15: Marc Chagall. « Jour de fete », 1914 | C15: temporaire | E15: 2026-11-01 | F15: Accrochage autour d'une toile de Chagall. | G15: https://www.mahj.org/fr/programme/marc-chagall-jour-de-fete-1914-31667 | I15: dates_a_confirmer | J15: site officiel | K15: 2026-09-19 | L15: claude
A16: musee-d-art-et-d-histoire-du-judaisme | B16: Chaim Kaliski. « Jim d'Etterbeek » | C16: temporaire | E16: 2026-12-13 | F16: Dessins a l'aquarelle et a l'encre de Chine : enfants, soldats, une cache, Anne Frank. | G16: https://www.mahj.org/fr/programme/chaim-kaliski-jim-detterbeek-31561 | I16: dates_a_confirmer | J16: site officiel | K16: 2026-09-19 | L16: claude
A17: musee-d-art-et-d-histoire-du-judaisme | B17: L'Ecole de Paris dans les collections du mahJ | C17: temporaire | D17: 2026-02-18 | F17: Accrochage consacre aux peintres de l'Ecole de Paris conserves par le musee. | G17: https://www.mahj.org/fr/programme/lecole-de-paris-dans-les-collections-du-mahj-31638 | I17: dates_a_confirmer | J17: site officiel | K17: 2026-09-19 | L17: claude
A18: musee-d-art-et-d-histoire-du-judaisme | B18: Itineraires d'oeuvres spoliees. Diane Esmond et Fedor Lowenstein | C18: temporaire | D18: 2026-02-18 | F18: Accrochage sur le parcours d'oeuvres spoliees et leur restitution. | G18: https://www.mahj.org/fr/programme/itineraires-doeuvres-spoliees-diane-esmond-et-fedor-lowenstein-31622 | I18: dates_a_confirmer | J18: site officiel | K18: 2026-09-19 | L18: claude
A19: musee-de-l-institut-du-monde-arabe | B19: Decouvrez le musee de l'IMA | C19: permanent | F19: Quatre niveaux organises autour de cinq thematiques : naissance d'une identite, des dieux a Dieu, deambuler dans une ville arabe, les expressions de la beaute, le corps soi et les autres. | G19: https://www.imarabe.org/fr/agenda/collections/decouvrez-musee-ima | H19: https://www.imarabe.org/sites/default/files/styles/card_330x200/public/2023-09/musee-ima-test.jpg | I19: complet | J19: site officiel | K19: 2026-09-19 | L19: claude
A20: musee-de-l-institut-du-monde-arabe | B20: Vive la mariee ! Algerie, Maroc, Tunisie | C20: temporaire | D20: 2026-09-29 | E20: 2027-02-28 | F20: Exposition-evenement consacree aux rituels et parures du mariage au Maghreb, accompagnee d'un temps fort de rencontres, cinema et concerts du 8 au 11 octobre. | G20: https://www.imarabe.org/fr/agenda/expositions-musee/vive-mariee | H20: https://www.imarabe.org/sites/default/files/styles/card_330x200/public/2026-07/hourouk-rhaiem-nuptiae-neapolis-2026.jpg | I20: complet | J20: site officiel | K20: 2026-09-19 | L20: claude
A21: musee-de-l-institut-du-monde-arabe | B21: La Palestine photographiee par Joss Dray | C21: temporaire | D21: 2026-09-19 | E21: 2026-11-01 | F21: Exposition de photographies de Joss Dray consacree a la Palestine. | G21: https://www.imarabe.org/fr/agenda/expositions-musee/palestine-photographiee-par-joss-dray | H21: https://www.imarabe.org/sites/default/files/styles/card_330x200/public/2026-07/gaza_065.jpg | I21: complet | J21: site officiel | K21: 2026-09-19 | L21: claude
A22: musee-de-la-vie-romantique | B22: Parcours de visite des collections | C22: permanent | F22: Hotel Scheffer-Renan, maison de l'atelier d'Ary Scheffer. Collections consacrees au romantisme parisien du XIXe siecle. Salon de the Rose Bakery et jardin. | G22: https://museevieromantique.paris.fr/les-collections/le-parcours-de-visite | H22: https://museevieromantique.paris.fr/sites/default/files/styles/metatag/public/images/2026-05/15%20mars%202026%40Mus%C3%A9e%20de%20la%20vie%20romantique-Paris%20Mus%C3%A9es-IP3%20PRESS%20BD002.JPG.webp | I22: complet | J22: site officiel | K22: 2026-09-19 | L22: claude
A24: statut : complet = publiable tel quel · les autres attendent une image ou une date de fin
A25: image_url = LOGO_MUSEE : expo permanente, utiliser le logo_url du lieu (onglet Lieux)
A26: Astuce : la balise <meta og:image> de la page donne presque toujours une image exploitable.

Sheet Horaires
A1: lieu_id | B1: jour_num | C1: jour | D1: ferme | E1: ouverture | F1: fermeture | G1: nocturne | H1: portee | I1: derniere_entree_min | J1: valide_du | K1: valide_au | L1: note
A2: musee-de-l-institut-du-monde-arabe | B2: 1 | C2: lundi | D2: oui | G2: non | H2: tout
A3: musee-de-l-institut-du-monde-arabe | B3: 2 | C3: mardi | D3: non | E3: 10:00 | F3: 18:00 | G3: non | H3: tout | I3: 45 | L3: Jours feries : horaires du week-end (10h-19h)
A4: musee-de-l-institut-du-monde-arabe | B4: 3 | C4: mercredi | D4: non | E4: 10:00 | F4: 18:00 | G4: non | H4: tout | I4: 45 | L4: Jours feries : horaires du week-end (10h-19h)
A5: musee-de-l-institut-du-monde-arabe | B5: 4 | C5: jeudi | D5: non | E5: 10:00 | F5: 18:00 | G5: non | H5: tout | I5: 45 | L5: Jours feries : horaires du week-end (10h-19h)
A6: musee-de-l-institut-du-monde-arabe | B6: 5 | C6: vendredi | D6: non | E6: 10:00 | F6: 18:00 | G6: non | H6: tout | I6: 45 | L6: Jours feries : horaires du week-end (10h-19h)
A7: musee-de-l-institut-du-monde-arabe | B7: 6 | C7: samedi | D7: non | E7: 10:00 | F7: 19:00 | G7: non | H7: tout | I7: 45 | L7: Jours feries : horaires du week-end (10h-19h)
A8: musee-de-l-institut-du-monde-arabe | B8: 7 | C8: dimanche | D8: non | E8: 10:00 | F8: 19:00 | G8: non | H8: tout | I8: 45 | L8: Jours feries : horaires du week-end (10h-19h)
A9: musee-d-art-et-d-histoire-du-judaisme | B9: 1 | C9: lundi | D9: oui | G9: non | H9: tout | K9: 2026-10-14
A10: musee-d-art-et-d-histoire-du-judaisme | B10: 2 | C10: mardi | D10: non | E10: 11:00 | F10: 18:00 | G10: non | H10: tout | I10: 45 | K10: 2026-10-14 | L10: Horaires annonces jusqu'au 14 octobre 2026, a reverifier ensuite
A11: musee-d-art-et-d-histoire-du-judaisme | B11: 3 | C11: mercredi | D11: non | E11: 11:00 | F11: 18:00 | G11: non | H11: tout | I11: 45 | K11: 2026-10-14 | L11: Horaires annonces jusqu'au 14 octobre 2026, a reverifier ensuite
A12: musee-d-art-et-d-histoire-du-judaisme | B12: 4 | C12: jeudi | D12: non | E12: 11:00 | F12: 18:00 | G12: non | H12: tout | I12: 45 | K12: 2026-10-14 | L12: Horaires annonces jusqu'au 14 octobre 2026, a reverifier ensuite
A13: musee-d-art-et-d-histoire-du-judaisme | B13: 5 | C13: vendredi | D13: non | E13: 11:00 | F13: 18:00 | G13: non | H13: tout | I13: 45 | K13: 2026-10-14 | L13: Horaires annonces jusqu'au 14 octobre 2026, a reverifier ensuite
A14: musee-d-art-et-d-histoire-du-judaisme | B14: 6 | C14: samedi | D14: non | E14: 10:00 | F14: 18:00 | G14: non | H14: tout | I14: 45 | K14: 2026-10-14 | L14: Horaires annonces jusqu'au 14 octobre 2026, a reverifier ensuite
A15: musee-d-art-et-d-histoire-du-judaisme | B15: 7 | C15: dimanche | D15: non | E15: 10:00 | F15: 18:00 | G15: non | H15: tout | I15: 45 | K15: 2026-10-14 | L15: Horaires annonces jusqu'au 14 octobre 2026, a reverifier ensuite
A16: musee-des-arts-decoratifs-union-centrale-des-arts-decoratifs | B16: 1 | C16: lundi | D16: oui | G16: non | H16: tout
A17: musee-des-arts-decoratifs-union-centrale-des-arts-decoratifs | B17: 2 | C17: mardi | D17: non | E17: 11:00 | F17: 18:00 | G17: non | H17: tout | I17: 45
A18: musee-des-arts-decoratifs-union-centrale-des-arts-decoratifs | B18: 3 | C18: mercredi | D18: non | E18: 11:00 | F18: 18:00 | G18: non | H18: tout | I18: 45
A19: musee-des-arts-decoratifs-union-centrale-des-arts-decoratifs | B19: 4 | C19: jeudi | D19: non | E19: 11:00 | F19: 18:00 | G19: non | H19: tout | I19: 45
A20: musee-des-arts-decoratifs-union-centrale-des-arts-decoratifs | B20: 5 | C20: vendredi | D20: non | E20: 11:00 | F20: 18:00 | G20: non | H20: tout | I20: 45
A21: musee-des-arts-decoratifs-union-centrale-des-arts-decoratifs | B21: 6 | C21: samedi | D21: non | E21: 11:00 | F21: 18:00 | G21: non | H21: tout | I21: 45
A22: musee-des-arts-decoratifs-union-centrale-des-arts-decoratifs | B22: 7 | C22: dimanche | D22: non | E22: 11:00 | F22: 18:00 | G22: non | H22: tout | I22: 45
A23: musee-des-arts-decoratifs-union-centrale-des-arts-decoratifs | B23: 4 | C23: jeudi | D23: non | E23: 18:00 | F23: 21:00 | G23: oui | H23: temporaire | I23: 45 | L23: Nocturne du jeudi : expositions temporaires et galerie des bijoux UNIQUEMENT, pas les collections permanentes
A24: fondation-cartier-pour-l-art-contemporain | B24: 1 | C24: lundi | D24: oui | G24: non | H24: tout
A25: fondation-cartier-pour-l-art-contemporain | B25: 2 | C25: mardi | D25: non | E25: 11:00 | F25: 19:00 | G25: non | H25: tout | L25: Ferme jusqu'a la reouverture du 22 octobre 2026
A26: fondation-cartier-pour-l-art-contemporain | B26: 3 | C26: mercredi | D26: non | E26: 11:00 | F26: 19:00 | G26: non | H26: tout | L26: Ferme jusqu'a la reouverture du 22 octobre 2026
A27: fondation-cartier-pour-l-art-contemporain | B27: 4 | C27: jeudi | D27: non | E27: 11:00 | F27: 19:00 | G27: non | H27: tout | L27: Ferme jusqu'a la reouverture du 22 octobre 2026
A28: fondation-cartier-pour-l-art-contemporain | B28: 5 | C28: vendredi | D28: non | E28: 11:00 | F28: 22:00 | G28: non | H28: tout | L28: Ferme jusqu'a la reouverture du 22 octobre 2026
A29: fondation-cartier-pour-l-art-contemporain | B29: 6 | C29: samedi | D29: non | E29: 11:00 | F29: 19:00 | G29: non | H29: tout | L29: Ferme jusqu'a la reouverture du 22 octobre 2026
A30: fondation-cartier-pour-l-art-contemporain | B30: 7 | C30: dimanche | D30: non | E30: 11:00 | F30: 19:00 | G30: non | H30: tout | L30: Ferme jusqu'a la reouverture du 22 octobre 2026
A31: fondation-cartier-pour-l-art-contemporain | B31: 5 | C31: vendredi | D31: non | E31: 19:00 | F31: 22:00 | G31: oui | H31: tout | L31: Nocturne du vendredi
A32: bourse-de-commerce-pinault-collection | B32: 1 | C32: lundi | D32: non | E32: 11:00 | F32: 19:00 | G32: non | H32: tout | L32: Ferme le mardi. Pas de nocturne le vendredi
A33: bourse-de-commerce-pinault-collection | B33: 2 | C33: mardi | D33: oui | G33: non | H33: tout
A34: bourse-de-commerce-pinault-collection | B34: 3 | C34: mercredi | D34: non | E34: 11:00 | F34: 19:00 | G34: non | H34: tout | L34: Ferme le mardi. Pas de nocturne le vendredi
A35: bourse-de-commerce-pinault-collection | B35: 4 | C35: jeudi | D35: non | E35: 11:00 | F35: 19:00 | G35: non | H35: tout | L35: Ferme le mardi. Pas de nocturne le vendredi
A36: bourse-de-commerce-pinault-collection | B36: 5 | C36: vendredi | D36: non | E36: 11:00 | F36: 19:00 | G36: non | H36: tout | L36: Ferme le mardi. Pas de nocturne le vendredi
A37: bourse-de-commerce-pinault-collection | B37: 6 | C37: samedi | D37: non | E37: 11:00 | F37: 19:00 | G37: non | H37: tout | L37: Ferme le mardi. Pas de nocturne le vendredi
A38: bourse-de-commerce-pinault-collection | B38: 7 | C38: dimanche | D38: non | E38: 11:00 | F38: 19:00 | G38: non | H38: tout | L38: Ferme le mardi. Pas de nocturne le vendredi
A39: musee-de-montmartre | B39: 1 | C39: lundi | D39: non | E39: 10:00 | F39: 19:00 | G39: non | H39: tout | I39: 45 | L39: Ouvert tous les jours. Les 25 decembre et 1er janvier : 11h30-18h
A40: musee-de-montmartre | B40: 2 | C40: mardi | D40: non | E40: 10:00 | F40: 19:00 | G40: non | H40: tout | I40: 45 | L40: Ouvert tous les jours. Les 25 decembre et 1er janvier : 11h30-18h
...

Sheet Fermetures
A1: lieu_id | B1: date | C1: libelle | D1: recurrent_annuel | E1: note
A2: musee-de-l-institut-du-monde-arabe | B2: 05-01 | C2: 1er mai | D2: oui
A3: musee-d-art-et-d-histoire-du-judaisme | B3: 01-01 | C3: 1er janvier | D3: oui
A4: musee-d-art-et-d-histoire-du-judaisme | B4: 05-01 | C4: 1er mai | D4: oui
A5: musee-des-arts-decoratifs-union-centrale-des-arts-decoratifs | B5: 01-01 | C5: 1er janvier | D5: oui
A6: musee-des-arts-decoratifs-union-centrale-des-arts-decoratifs | B6: 05-01 | C6: 1er mai | D6: oui
A7: musee-des-arts-decoratifs-union-centrale-des-arts-decoratifs | B7: 12-25 | C7: 25 decembre | D7: oui
A8: fondation-cartier-pour-l-art-contemporain | B8: 01-01 | C8: 1er janvier | D8: oui
A9: fondation-cartier-pour-l-art-contemporain | B9: 05-01 | C9: 1er mai | D9: oui
A10: fondation-cartier-pour-l-art-contemporain | B10: 12-25 | C10: 25 decembre | D10: oui
A11: fondation-cartier-pour-l-art-contemporain | B11: 12-24 | C11: 24 decembre | D11: oui | E11: Fermeture anticipee a 18h, pas une fermeture totale
A12: fondation-cartier-pour-l-art-contemporain | B12: 12-31 | C12: 31 decembre | D12: oui | E12: Fermeture anticipee a 18h, pas une fermeture totale
A13: bourse-de-commerce-pinault-collection | B13: 05-01 | C13: 1er mai | D13: oui
A14: bourse-de-commerce-pinault-collection | B14: 2026-08-26 | C14: Musee en mouvement | D14: non | E14: Du 26 aout au 5 octobre 2026 : montage de l'exposition Remember Me, tarifs reduits
A15: musee-de-la-musique | B15: 01-01 | C15: 1er janvier | D15: oui
A16: musee-de-la-musique | B16: 05-01 | C16: 1er mai | D16: oui
A17: musee-de-la-musique | B17: 12-25 | C17: 25 decembre | D17: oui
A18: musee-de-la-vie-romantique | B18: 01-01 | C18: 1er janvier | D18: oui
A19: musee-de-la-vie-romantique | B19: 05-01 | C19: 1er mai | D19: oui
A20: musee-de-la-vie-romantique | B20: 12-25 | C20: 25 decembre | D20: oui
A22: date au format MM-JJ si recurrent_annuel = oui, sinon AAAA-MM-JJ.

Sheet Suivi
A1: Avancement
A3: Lieux au total | B3: =COUNTA(Lieux!$B$2:$B$58) -> 57
A4: Vérifiés | B4: =COUNTIF(Lieux!$K$2:$K$58,"vérifié") -> 9
A5: Restants | B5: =COUNTIF(Lieux!$K$2:$K$58,"à vérifier") -> 48
A6: Avec URL expos | B6: =COUNTA(Lieux!$H$2:$H$58) -> 17
A7: % avancement | B7: =IFERROR(COUNTIF(Lieux!$K$2:$K$58,"vérifié")/COUNTA(Lieux!$B$2:$B$58),0) -> 0.15789474
A10: Par famille
A11: famille | B11: lieux | C11: vérifiés
A12: paris_musees | B12: =COUNTIF(Lieux!$C$2:$C$58,$A12) -> 12 | C12: =COUNTIFS(Lieux!$C$2:$C$58,$A12,Lieux!$K$2:$K$58,"vérifié") -> 1
A13: musee_national | B13: =COUNTIF(Lieux!$C$2:$C$58,$A13) -> 19 | C13: =COUNTIFS(Lieux!$C$2:$C$58,$A13,Lieux!$K$2:$K$58,"vérifié") -> 0
A14: cmn | B14: =COUNTIF(Lieux!$C$2:$C$58,$A14) -> 4 | C14: =COUNTIFS(Lieux!$C$2:$C$58,$A14,Lieux!$K$2:$K$58,"vérifié") -> 0
A15: militaire | B15: =COUNTIF(Lieux!$C$2:$C$58,$A15) -> 2 | C15: =COUNTIFS(Lieux!$C$2:$C$58,$A15,Lieux!$K$2:$K$58,"vérifié") -> 0
A16: prive_assoc | B16: =COUNTIF(Lieux!$C$2:$C$58,$A16) -> 13 | C16: =COUNTIFS(Lieux!$C$2:$C$58,$A16,Lieux!$K$2:$K$58,"vérifié") -> 8
A17: autre_public | B17: =COUNTIF(Lieux!$C$2:$C$58,$A17) -> 7 | C17: =COUNTIFS(Lieux!$C$2:$C$58,$A17,Lieux!$K$2:$K$58,"vérifié") -> 0
